Workbook
Name Baseline: UW!$C$441
Name Beta1: '[7]BBSW Curve'!$G$3
Name Beta1: 'BBSW Curve'!$G$3
Name Beta1: 'BBSW Curve'!$G$3
Name Beta2: '[7]BBSW Curve'!$G$4
Name Beta2: 'BBSW Curve'!$G$4
Name Beta2: 'BBSW Curve'!$G$4
Name Beta3: '[7]BBSW Curve'!$G$5
Name Beta3: 'BBSW Curve'!$G$5
Name Beta3: 'BBSW Curve'!$G$5
Name Beta4: '[7]BBSW Curve'!$G$6
Name Beta4: 'BBSW Curve'!$G$6
Name Beta4: 'BBSW Curve'!$G$6
Name Cash_on_Deposit_YesNo: [7]UW!$J$61
Name Cash_on_Deposit_YesNo: UW!$J$61
Name ddAccountClass: OFFSET( '[1]Dropdown Lists'!$AA$3,0,0,'[1]Dropdown Lists'!$AC$1,1)
Name ddFinPeriodID: OFFSET('[1]Dropdown Lists'!$D$3,0,0,'[1]Dropdown Lists'!$E$1,1)
Name ddSubAccountCode: OFFSET('[1]Dropdown Lists'!$W$3,0,0,'[1]Dropdown Lists'!$Y$1,3)
Name Debt: UW!$A$779
Name Dev_Budget: 'Dev Bdgt'!$C$2
Name Expense_Calcs: '[2]Model Inputs & Calcs'!$B$42:$N$65
Name Expense_Details: UW!$C$554
Name Expense_Match: '[2]Model Inputs & Calcs'!$B$42:$B$65
Name Expense_Yr_Match: '[2]Model Inputs & Calcs'!$B$42:$N$42
Name Home: UW!$D$4
Name IFS: [7]UW!#REF!
Name IFS: UW!#REF!
Name Lambda1: '[7]BBSW Curve'!$G$7
Name Lambda1: 'BBSW Curve'!$G$7
Name Lambda1: 'BBSW Curve'!$G$7
Name Lambda2: '[7]BBSW Curve'!$G$8
Name Lambda2: 'BBSW Curve'!$G$8
Name Lambda2: 'BBSW Curve'!$G$8
Name Lease_End_Date: [3]UW!$A$400
Name Mth_Bud: 'Mthly Bdgt'!$B$2:$P$706
Name Mth_Bud: 'Mthly Bdgt'!$B$2:$P$706
Name MthBud: '[3]Mthly Bdgt'!$B$2:$P$706
Name nActualLedger: [1]Global!$C$2
Name nBudgetLedger: [4]!tblBudgetLedger[Budget Ledger]
Name nConnection: [5]Global!$A$2
Name NoSubAccount: '[1]Dropdown Lists'!$BD$2
Name On_Deposit_Equity_Amount: [7]UW!$E$45
Name On_Deposit_Equity_Amount: UW!$E$45
Name On_Deposit_Equity_InDate: [7]UW!$J$62
Name On_Deposit_Equity_InDate: UW!$J$62
Name On_Deposit_Equity_OutDate: [7]UW!$J$63
Name On_Deposit_Equity_OutDate: UW!$J$63
Name Proforma_Annual: UW!$C$76
Name Proforma_Monthly: UW!$D$612
Name Sensitivity: UW!$B$867
Name Start_Mth: [7]UW!$D$95
Name Start_Mth: UW!$D$95
Name Start_Mth: UW!$D$95
Name StartMth: [3]UW!$D$95
Name Total_Equity: [7]UW!$M$13
Name Total_Equity: UW!$M$13
Name Unit_Mix: 'Comps & Unit Mix'!$AV$206
Name UnitMix: '[6]Comps & Unit Mix'!#REF!

Sheet Notes
A2: - Add sensitivity to DU GPR (cell d106)
A3: -link concessions (one time) to lease-up
A4: - create output page
A5: - use Gympie P/L for expense line reference
A6: - create lease up component for expansions
A7: - Add RV GPR to Property and Budget Tabs
A8: - Add Warehouse Income to DCF and Property, Budget
A9: - Add secondary Dev Budget
A10: - remove bad debt from expense ratio?
A11: - Add Other real estate income to Mthly Bdgt
A12: - Add another refinance assumption
A13: - Add RV Parking in Unit Mix
... A35: - "Mth_Bud" = VLOOKUP Chart for Concessions Calc

Sheet Output
F2: 1-km | G2: 3-km | H2: 5-km | K2: =UW!C6 -> Property Description | O2: Metrics Summary - 10 Year | U2: ='Return Distr.'!B127 -> Unitholder Position | X2: ='Return Distr.'!H127 -> 1 | Y2: ='Return Distr.'!I127 -> 2 | Z2: ='Return Distr.'!J127 -> 3 | AA2: ='Return Distr.'!K127 -> 4 | AB2: ='Return Distr.'!L127 -> 5 | AC2: ='Return Distr.'!M127 -> 6 | AD2: ='Return Distr.'!N127 -> 7 | AE2: ='Return Distr.'!O127 -> 8 | ... AG2: ='Return Distr.'!Q127 -> 10
C3: Population | F3: =UW!N59 -> 0 | G3: =UW!N60 -> 0 | H3: =UW!N61 -> 0 | K3: =UW!C7 -> Property Name | M3: =UW!D7 -> 0 | O3: =UW!#REF! -> #REF! | Q3: =UW!#REF! -> #REF!
C4: Number of Households | F4: 3311 | G4: 34218 | H4: 94547 | K4: Address | M4: =CONCATENATE(UW!D8,", ", UW!D9," ",UW!D10) -> , | O4: =UW!#REF! -> #REF! | Q4: =UW!#REF! -> #REF! | U4: ='Return Distr.'!B129 -> Net Property Income | X4: ='Return Distr.'!H129 -> 0 | Y4: ='Return Distr.'!I129 -> 0 | Z4: ='Return Distr.'!J129 -> 0 | AA4: ='Return Distr.'!K129 -> 0 | AB4: ='Return Distr.'!L129 -> 0 | AC4: ='Return Distr.'!M129 -> 0 | AD4: ='Return Distr.'!N129 -> 0 | AE4: ='Return Distr.'!O129 -> 0 | ... AG4: ='Return Distr.'!Q129 -> 0
C5: Average Household Size | F5: =F3/F4 -> 0 | G5: 3.01 | H5: 2.95 | K5: =UW!C12 -> Parcel Size | L5: =UW!#REF! -> #REF! | M5: =UW!D12 -> 0 | O5: =UW!#REF! -> #REF! | Q5: =UW!#REF! -> #REF! | U5: ='Return Distr.'!B130 -> Total Property Related Costs | X5: ='Return Distr.'!H130 -> -141154.2 | Y5: ='Return Distr.'!I130 -> -148182.53 | Z5: ='Return Distr.'!J130 -> -155561.7 | AA5: ='Return Distr.'!K130 -> -163309.22 | AB5: ='Return Distr.'!L130 -> -171443.51 | AC5: ='Return Distr.'!M130 -> -179983.88 | AD5: ='Return Distr.'!N130 -> -188950.64 | AE5: ='Return Distr.'!O130 -> -198365.09 | ... AG5: ='Return Distr.'!Q130 -> -218627.67
C6: Households That Rent | F6: =UW!N53 -> 0 | G6: =UW!N54 -> 0 | H6: =UW!N55 -> 0 | K6: =UW!C16 -> Traffic Count | L6: =UW!G16 -> 0 | M6: =UW!D16 -> 0 | O6: =UW!I16 -> Equity Multiple | Q6: =UW!J16 -> #DIV/0! | U6: ='Return Distr.'!B131 -> Net Income | X6: ='Return Distr.'!H131 -> -141154.2 | Y6: ='Return Distr.'!I131 -> -148182.53 | Z6: ='Return Distr.'!J131 -> -155561.7 | AA6: ='Return Distr.'!K131 -> -163309.22 | AB6: ='Return Distr.'!L131 -> -171443.51 | AC6: ='Return Distr.'!M131 -> -179983.88 | AD6: ='Return Distr.'!N131 -> -188950.64 | AE6: ='Return Distr.'!O131 -> -198365.09 | ... AG6: ='Return Distr.'!Q131 -> -218627.67
C7: % of Households That Rent | F7: =F6/F4 -> 0 | G7: =G6/G4 -> 0 | H7: =H6/H4 -> 0 | K7: =UW!C17 -> Renovated | M7: =UW!D17 -> 0 | O7: =CONCATENATE("Land ",UW!I17) -> Land Stab. YoC - Untrended | Q7: =UW!J17 -> #DIV/0!
C8: Storage Supply | F8: =UW!N50 -> 1400 | G8: =UW!N51 -> 7490 | H8: =UW!N52 -> 7490 | K8: =UW!C18 -> Manager Apartment? | M8: =UW!D18 -> 0 | O8: =UW!I18 -> Stab. YoC - Untrended (Norm.) | Q8: =UW!J18 -> #DIV/0! | U8: ='Return Distr.'!B133 -> Indirect Costs
C9: Storage Supply Per Capita | F9: =F8/F3 -> #DIV/0! | G9: =G8/G3 -> #DIV/0! | H9: =H8/H3 -> #DIV/0! | K9: =UW!C19 -> Rental Summary | M9: =UW!D19 -> 0 | O9: =UW!I19 -> Stab. YoC - Trended | Q9: =UW!J19 -> #DIV/0! | U9: ='Return Distr.'!B135 -> Interest | X9: ='Return Distr.'!H135 -> #DIV/0! | Y9: ='Return Distr.'!I135 -> #DIV/0! | Z9: ='Return Distr.'!J135 -> #DIV/0! | AA9: ='Return Distr.'!K135 -> 50.549895 | AB9: ='Return Distr.'!L135 -> 0 | AC9: ='Return Distr.'!M135 -> 0 | AD9: ='Return Distr.'!N135 -> 0 | AE9: ='Return Distr.'!O135 -> 0 | ... AG9: ='Return Distr.'!Q135 -> 0
K10: =UW!C20 -> Gross SM (Entire Facility) | M10: =UW!#REF! -> #REF! | O10: =UW!I20 -> Stab. YoC - Trended (Norm.) | Q10: =UW!J20 -> #DIV/0! | U10: ='Return Distr.'!B136 -> Fund Management Fee | X10: ='Return Distr.'!H136 -> 0 | Y10: ='Return Distr.'!I136 -> 0 | Z10: ='Return Distr.'!J136 -> 0 | AA10: ='Return Distr.'!K136 -> 0 | AB10: ='Return Distr.'!L136 -> 0 | AC10: ='Return Distr.'!M136 -> 0 | AD10: ='Return Distr.'!N136 -> 0 | AE10: ='Return Distr.'!O136 -> 0 | ... AG10: ='Return Distr.'!Q136 -> 0
K11: Construction Type | M11: Dado - steel frame/tilt up | U11: ='Return Distr.'!B137 -> Total Indirect Costs | X11: ='Return Distr.'!H137 -> #DIV/0! | Y11: ='Return Distr.'!I137 -> #DIV/0! | Z11: ='Return Distr.'!J137 -> #DIV/0! | AA11: ='Return Distr.'!K137 -> #DIV/0! | AB11: ='Return Distr.'!L137 -> #DIV/0! | AC11: ='Return Distr.'!M137 -> #DIV/0! | AD11: ='Return Distr.'!N137 -> #DIV/0! | AE11: ='Return Distr.'!O137 -> #DIV/0! | ... AG11: ='Return Distr.'!Q137 -> #DIV/0!
K12: =UW!C21 -> Net Rentable SM (Storage Only) | M12: =UW!#REF! -> #REF! | O12: Submarket
K13: =UW!C22 -> # Storage Units | M13: =UW!#REF! -> #REF! | O13: Surrounding Uses | Q13: Industrial/Residential/Retail | U13: ='Return Distr.'!B139 -> Total Reserve Drawdown | X13: ='Return Distr.'!H139 -> #DIV/0! | Y13: ='Return Distr.'!I139 -> #DIV/0! | Z13: ='Return Distr.'!J139 -> #DIV/0! | AA13: ='Return Distr.'!K139 -> #DIV/0! | AB13: ='Return Distr.'!L139 -> #DIV/0! | AC13: ='Return Distr.'!M139 -> #DIV/0! | AD13: ='Return Distr.'!N139 -> #DIV/0! | AE13: ='Return Distr.'!O139 -> #DIV/0! | ... AG13: ='Return Distr.'!Q139 -> #DIV/0!
K14: =UW!C23 -> Average Unit Size (Storage) | M14: =UW!#REF! -> #REF! | O14: =UW!L51 -> Supply (3-km) | Q14: =G9 -> #DIV/0! | U14: ='Return Distr.'!B141 -> Distributable Income | X14: ='Return Distr.'!H141 -> #DIV/0! | Y14: ='Return Distr.'!I141 -> #DIV/0! | Z14: ='Return Distr.'!J141 -> #DIV/0! | AA14: ='Return Distr.'!K141 -> #DIV/0! | AB14: ='Return Distr.'!L141 -> #DIV/0! | AC14: ='Return Distr.'!M141 -> #DIV/0! | AD14: ='Return Distr.'!N141 -> #DIV/0! | AE14: ='Return Distr.'!O141 -> #DIV/0! | ... AG14: ='Return Distr.'!Q141 -> #DIV/0!
K15: =UW!C25 -> Occupancy | L15: =UW!D27 -> No | M15: =UW!D20 -> 0 | O15: =UW!L52 -> Supply (5-km) | Q15: =H9 -> #DIV/0!
K16: =UW!C26 -> Asking Rents | M16: =UW!D21 -> 0 | O16: =UW!L54 -> HH that Rent (3-km) | Q16: =G7 -> 0 | U16: ='Return Distr.'!B143 -> Equity Repatriation | X16: ='Return Distr.'!H143 -> 0 | Y16: ='Return Distr.'!I143 -> 0 | Z16: ='Return Distr.'!J143 -> #DIV/0! | AA16: ='Return Distr.'!K143 -> 835.53546 | AB16: ='Return Distr.'!L143 -> 0 | AC16: ='Return Distr.'!M143 -> 0 | AD16: ='Return Distr.'!N143 -> 0 | AE16: ='Return Distr.'!O143 -> 0 | ... AG16: ='Return Distr.'!Q143 -> 0
K17: =UW!F21 -> Net Rentable SM (Office) | M17: =UW!D22 -> 0 | O17: =UW!L55 -> HH that Rent (5-km) | Q17: =H7 -> 0 | U17: ='Return Distr.'!#REF! -> #REF! | X17: ='Return Distr.'!#REF! -> #REF! | Y17: ='Return Distr.'!#REF! -> #REF! | Z17: ='Return Distr.'!#REF! -> #REF! | AA17: ='Return Distr.'!#REF! -> #REF! | AB17: ='Return Distr.'!#REF! -> #REF! | AC17: ='Return Distr.'!#REF! -> #REF! | AD17: ='Return Distr.'!#REF! -> #REF! | AE17: ='Return Distr.'!#REF! -> #REF! | ... AG17: ='Return Distr.'!#REF! -> #REF!
K18: =UW!F28 -> Warehouse NLA | M18: =UW!G28 -> 0 | O18: =UW!L60 -> Population (3-km) | Q18: =UW!N60 -> 0
K19: =UW!F29 -> # Warehouse Units | M19: =UW!G29 -> 15 | O19: =UW!L61 -> Population (5-km) | Q19: =UW!N61 -> 0 | U19: ='Return Distr.'!B144 -> Equity | X19: ='Return Distr.'!H144 -> #DIV/0! | Y19: ='Return Distr.'!I144 -> #DIV/0! | Z19: ='Return Distr.'!J144 -> #DIV/0! | AA19: ='Return Distr.'!K144 -> #DIV/0! | AB19: ='Return Distr.'!L144 -> #DIV/0! | AC19: ='Return Distr.'!M144 -> #DIV/0! | AD19: ='Return Distr.'!N144 -> #DIV/0! | AE19: ='Return Distr.'!O144 -> #DIV/0! | ... AG19: ='Return Distr.'!Q144 -> #DIV/0!
K20: Gross Potential Rent (Storage) | L20: =UW!D26 -> #DIV/0! | M20: =UW!G33 -> 0
U21: ='Return Distr.'!B146 -> Distributions Per Unit | X21: ='Return Distr.'!H146 -> #DIV/0! | Y21: ='Return Distr.'!I146 -> #DIV/0! | Z21: ='Return Distr.'!J146 -> #DIV/0! | AA21: ='Return Distr.'!K146 -> #DIV/0! | AB21: ='Return Distr.'!L146 -> #DIV/0! | AC21: ='Return Distr.'!M146 -> #DIV/0! | AD21: ='Return Distr.'!N146 -> #DIV/0! | AE21: ='Return Distr.'!O146 -> #DIV/0! | ... AG21: ='Return Distr.'!Q146 -> #DIV/0!
U22: ='Return Distr.'!B147 -> Distributions Per Unit (%) | X22: ='Return Distr.'!H147 -> #DIV/0! | Y22: ='Return Distr.'!I147 -> #DIV/0! | Z22: ='Return Distr.'!J147 -> #DIV/0! | AA22: ='Return Distr.'!K147 -> #DIV/0! | AB22: ='Return Distr.'!L147 -> #DIV/0! | AC22: ='Return Distr.'!M147 -> #DIV/0! | AD22: ='Return Distr.'!N147 -> #DIV/0! | AE22: ='Return Distr.'!O147 -> #DIV/0! | ... AG22: ='Return Distr.'!Q147 -> #DIV/0!
U23: Debt | X23: ='Return Distr.'!H148 -> #DIV/0! | Y23: ='Return Distr.'!I148 -> #DIV/0! | Z23: ='Return Distr.'!J148 -> -835.53546 | AA23: ='Return Distr.'!K148 -> -835.53546 | AB23: ='Return Distr.'!L148 -> 0 | AC23: ='Return Distr.'!M148 -> 0 | AD23: ='Return Distr.'!N148 -> 0 | AE23: ='Return Distr.'!O148 -> 0 | ... AG23: ='Return Distr.'!Q148 -> 0
K24: Property | O24: Loan | P24: =UW!E40 -> Initial Loan | Q24: Refi 1 | R24: Refi 2 | U24: ='Return Distr.'!B149 -> LVR | X24: ='Return Distr.'!H149 -> #DIV/0! | Y24: ='Return Distr.'!I149 -> #DIV/0! | Z24: ='Return Distr.'!J149 -> 0.44987406 | AA24: ='Return Distr.'!K149 -> 0.84045144 | AB24: ='Return Distr.'!L149 -> #DIV/0! | AC24: ='Return Distr.'!M149 -> #DIV/0! | AD24: ='Return Distr.'!N149 -> #DIV/0! | AE24: ='Return Distr.'!O149 -> #DIV/0! | ... AG24: ='Return Distr.'!Q149 -> #DIV/0!
K25: =UW!C12 -> Parcel Size | L25: =UW!#REF! -> #REF! | M25: =UW!D12 -> 0 | O25: =UW!D47 -> Total Loan | P25: =UW!E47 -> #DIV/0! | Q25: =UW!F47 -> -835.53546 | R25: =UW!G47 -> 0
K26: Total Building Size | L26: =UW!D21 -> 0 | M26: =UW!D20 -> 0 | O26: =UW!D49 -> Origination Fee | P26: =UW!E49 -> 0 | Q26: =UW!F49 -> 0 | R26: =UW!G49 -> 0 | U26: ='Return Distr.'!B151 -> Capital Value (DCF) | X26: ='Return Distr.'!H151 -> -3307.0063 | Y26: ='Return Distr.'!I151 -> -2627.9427 | Z26: ='Return Distr.'!J151 -> -1857.2653 | AA26: ='Return Distr.'!K151 -> -994.15079 | AB26: ='Return Distr.'!L151 -> 0 | AC26: ='Return Distr.'!M151 -> 0 | AD26: ='Return Distr.'!N151 -> 0 | AE26: ='Return Distr.'!O151 -> 0 | ... AG26: ='Return Distr.'!Q151 -> 0
K27: NLA Breakdown | L27: =UW!D21 -> 0 | M27: =UW!G29 -> 15 | O27: =UW!D52 -> Basis | P27: =UW!E52 -> BBSY | Q27: =UW!F52 -> BBSY | R27: =UW!G52 -> BBSY | U27: ='Return Distr.'!B152 -> Capital Value (Cap Rate) | X27: ='Return Distr.'!H152 -> 0 | Y27: ='Return Distr.'!I152 -> 0 | Z27: ='Return Distr.'!J152 -> 0 | AA27: ='Return Distr.'!K152 -> 0 | AB27: ='Return Distr.'!L152 -> 0 | AC27: ='Return Distr.'!M152 -> 0 | AD27: ='Return Distr.'!N152 -> 0 | AE27: ='Return Distr.'!O152 -> 0 | ... AG27: ='Return Distr.'!Q152 -> 0
K28: Units | L28: =UW!D22 -> 0 | M28: =UW!G28 -> 0 | O28: =UW!D53 -> Type | P28: =UW!E53 -> Floating | Q28: =UW!F53 -> Floating | R28: =UW!G53 -> Floating
K29: =K20 -> Gross Potential Rent (Storage) | L29: =L20 -> #DIV/0! | M29: =M20 -> 0 | O29: =UW!D54 -> Index (term average) | P29: =UW!E54 -> 0.039 | Q29: =UW!F54 -> 0.039 | R29: =UW!G54 -> 0.039 | U29: NTA Timeline (DCF Value) | X29: =X42 -> 1 | Y29: =Y42 -> 2 | Z29: =Z42 -> 3 | AA29: =AA42 -> 4 | AB29: =AB42 -> 5 | AC29: =AC42 -> 6 | AD29: =AD42 -> 7 | AE29: =AE42 -> 8 | ... AG29: =AG42 -> 10
O30: =UW!D55 -> Spread | P30: =UW!E55 -> 0.0215 | Q30: =UW!F55 -> 0.0215 | R30: =UW!G55 -> 0.0215 | U30: NTA per Unit | X30: ='Return Distr.'!H153 -> #DIV/0! | Y30: ='Return Distr.'!I153 -> #DIV/0! | Z30: ='Return Distr.'!J153 -> #DIV/0! | AA30: ='Return Distr.'!K153 -> #DIV/0! | AB30: ='Return Distr.'!L153 -> #DIV/0! | AC30: ='Return Distr.'!M153 -> #DIV/0! | AD30: ='Return Distr.'!N153 -> #DIV/0! | AE30: ='Return Distr.'!O153 -> #DIV/0! | ... AG30: ='Return Distr.'!Q153 -> #DIV/0!
O31: =UW!D56 -> Rate | P31: =UW!E56 -> 0.0605 | Q31: =UW!F56 -> 0.0605 | R31: =UW!G56 -> 0.0605
K32: Purchase | O32: =UW!D58 -> I/O Years | P32: =UW!E58 -> 2.75 | Q32: =UW!F58 -> 1.25 | R32: =UW!G58 -> 0 | U32: ='Return Distr.'!B153 -> Net Tangible Assets (DCF Value) | X32: 1 | Y32: =X32+1 -> 2 | Z32: =Y32+1 -> 3 | AA32: =Z32+1 -> 4 | AB32: =AA32+1 -> 5 | AC32: =AB32+1 -> 6 | AD32: =AC32+1 -> 7 | AE32: =AD32+1 -> 8 | AF32: =AE32+1 -> 9 | AG32: =AF32+1 -> 10
K33: =UW!L16 -> Purchase Price | L33: =M33/($L$27+$M$27) -> 0 | M33: =UW!M16 -> 0 | O33: =UW!D62 -> Start Date | P33: =UW!E62 -> 46112 | Q33: =UW!F62 -> 47149 | R33: =UW!G62 -> 48638 | U33: ='Return Distr.'!B156 -> 10 | V33: ='Return Distr.'!C156 -> #VALUE! | W33: ='Return Distr.'!G156 -> #DIV/0! | X33: ='Return Distr.'!H156 -> #DIV/0! | Y33: ='Return Distr.'!I156 -> #DIV/0! | Z33: ='Return Distr.'!J156 -> #DIV/0! | AA33: ='Return Distr.'!K156 -> #DIV/0! | AB33: ='Return Distr.'!L156 -> #DIV/0! | AC33: ='Return Distr.'!M156 -> #DIV/0! | AD33: ='Return Distr.'!N156 -> #DIV/0! | ... AG33: ='Return Distr.'!Q156 -> #DIV/0!
K34: Total Consideration w/o Reserves | L34: =M34/($L$27+$M$27) -> #DIV/0! | M34: =UW!M31-(UW!M26-UW!M41)-UW!M30 -> #DIV/0! | O34: =UW!D63 -> Payoff Month | P34: =UW!E63 -> 33 | Q34: =UW!F63 -> 48 | R34: =UW!G63 -> 48 | U34: ='Return Distr.'!B157 -> 7 | V34: ='Return Distr.'!C157 -> #VALUE! | W34: ='Return Distr.'!G157 -> #DIV/0! | X34: ='Return Distr.'!H157 -> #DIV/0! | Y34: ='Return Distr.'!I157 -> #DIV/0! | Z34: ='Return Distr.'!J157 -> #DIV/0! | AA34: ='Return Distr.'!K157 -> #DIV/0! | AB34: ='Return Distr.'!L157 -> #DIV/0! | AC34: ='Return Distr.'!M157 -> #DIV/0! | AD34: ='Return Distr.'!N157 -> #DIV/0!
K35: Total Consideration w/ Reserves | L35: =M35/($L$27+$M$27) -> #DIV/0! | M35: =UW!M37 -> #DIV/0! | U35: ='Return Distr.'!B158 -> 5 | V35: ='Return Distr.'!C158 -> #VALUE! | W35: ='Return Distr.'!G158 -> #DIV/0! | X35: ='Return Distr.'!H158 -> #DIV/0! | Y35: ='Return Distr.'!I158 -> #DIV/0! | Z35: ='Return Distr.'!J158 -> #DIV/0! | AA35: ='Return Distr.'!K158 -> #DIV/0! | AB35: ='Return Distr.'!L158 -> #DIV/0!
K36: Projected Closing Date | M36: =UW!I12 -> 46112 | O36: =UW!I46 -> Fee Structure
O37: =UW!I48 -> Shares Issued | R37: =UW!J48 -> NA | X37: 1 | Y37: =X37+1 -> 2 | Z37: =Y37+1 -> 3 | AA37: =Z37+1 -> 4 | AB37: =AA37+1 -> 5 | AC37: =AB37+1 -> 6 | AD37: =AC37+1 -> 7 | AE37: =AD37+1 -> 8 | AF37: =AE37+1 -> 9 | AG37: =AF37+1 -> 10
K38: Disposition | O38: =UW!I49 -> Share Price | R38: =UW!J49 -> 1 | U38: ='Return Distr.'!B162 -> 10 | V38: ='Return Distr.'!C162 -> #VALUE! | W38: ='Return Distr.'!G162 -> #DIV/0! | X38: ='Return Distr.'!H162 -> #DIV/0! | Y38: ='Return Distr.'!I162 -> #DIV/0! | Z38: ='Return Distr.'!J162 -> #DIV/0! | AA38: ='Return Distr.'!K162 -> #DIV/0! | AB38: ='Return Distr.'!L162 -> #DIV/0! | AC38: ='Return Distr.'!M162 -> 0 | AD38: ='Return Distr.'!N162 -> 0 | ... AG38: ='Return Distr.'!Q162 -> 0
K39: =UW!I29 -> Gross Sale | L39: =M39/($L$27+$M$27) -> 0 | M39: =UW!J29 -> 0 | O39: =UW!I50 -> Asset Management Fee | R39: =UW!J50 -> 0.008 | U39: ='Return Distr.'!B163 -> 7 | V39: ='Return Distr.'!C163 -> #VALUE! | W39: ='Return Distr.'!G163 -> #DIV/0! | X39: ='Return Distr.'!H163 -> #DIV/0! | Y39: ='Return Distr.'!I163 -> #DIV/0! | Z39: ='Return Distr.'!J163 -> #DIV/0! | AA39: ='Return Distr.'!K163 -> #DIV/0! | AB39: ='Return Distr.'!L163 -> #DIV/0! | AC39: ='Return Distr.'!M163 -> 0 | AD39: ='Return Distr.'!N163 -> 0
K40: =UW!I31 -> Net Sale | L40: =M40/($L$27+$M$27) -> 0 | M40: =UW!J31 -> 0 | O40: =UW!I51 -> Acquisition Fee | R40: =UW!J51 -> 0 | U40: ='Return Distr.'!B164 -> 5 | V40: ='Return Distr.'!C164 -> #VALUE! | W40: ='Return Distr.'!G164 -> #DIV/0! | X40: ='Return Distr.'!H164 -> #DIV/0! | Y40: ='Return Distr.'!I164 -> #DIV/0! | Z40: ='Return Distr.'!J164 -> #DIV/0! | AA40: ='Return Distr.'!K164 -> #DIV/0! | AB40: ='Return Distr.'!L164 -> #DIV/0!
K41: =UW!I34 -> Net Proceeds | L41: =M41/($L$27+$M$27) -> #DIV/0! | M41: =UW!J34 -> #DIV/0! | O41: =UW!I52 -> Development Fee | R41: =UW!J52 -> 0.05
...

Sheet Expansion
C2: Expansion
C3: GFA | D3: ='Unit Mix Generator'!P19 -> 0
C4: NLA | D4: ='Unit Mix Generator'!Q19 -> 0
C5: Av Size | D5: ='Unit Mix Generator'!C7 -> 0
C6: # of Units | D6: =D4/D5 -> #DIV/0!
C7: Starting Occ. | D7: =E16 -> 0
C8: Stabilisation | D8: 0.85 | F8: =D10/12 -> 1
C9: Occ Month | D9: =OFFSET($D$14,,1+COUNTIF($E$16:$O$16,D16)) -> 0 | E9: **12 months construction from 14 April 2021 cross referenced on UW page
C10: Stabilisation Month | D10: =OFFSET($D$15,,11-COUNTIF($E$16:$N$16,$O$16)) -> 12
C11: Discount Exp | D11: 0.1
C13: Lease-Up Timeline Expansion | E13: 1 | F13: =E13+1 -> 2 | G13: =F13+1 -> 3 | H13: =G13+1 -> 4 | I13: =H13+1 -> 5 | J13: =I13+1 -> 6 | K13: =J13+1 -> 7 | L13: =K13+1 -> 8 | M13: =L13+1 -> 9 | ... O13: =N13+1 -> 11
C14: Start Month | D14: =IF(E17>0,E14,IF(F17>0,F14,IF(G17>0,G14,IF(H17>0,H14,IF(I17>0,I14))))) -> FALSE | E14: 1 | F14: =E15+1 -> 13 | G14: =F15+1 -> 19 | H14: 46 | I14: 49 | J14: =I15+1 -> 61 | K14: =J15+1 -> 73 | L14: =K15+1 -> 85 | M14: =L15+1 -> 94 | N14: =M15+1 -> 109 | O14: =N15+1 -> 121
C15: End Month | E15: 12 | F15: 18 | G15: 36 | H15: 48 | I15: 60 | J15: 72 | K15: 84 | L15: 93 | M15: 108 | N15: 120 | O15: 132
C16: Year End Occupancy | E16: 0 | F16: 0 | G16: 0 | H16: 0 | I16: 0 | J16: 0 | K16: 0 | L16: 0 | M16: 0 | N16: 0 | O16: 0
C17: Average Monthly Lease-Up | E17: =(E16-D7)/(E15-E14)*$D$4 -> 0 | F17: =(F16-E16)/(F15-F14)*$D$4 -> 0 | G17: =(G16-F16)/(G15-G14)*$D$4 -> 0 | H17: =(H16-G16)/(H15-H14)*$D$4 -> 0 | I17: =(I16-H16)/(I15-I14)*$D$4 -> 0 | J17: =(J16-I16)/(J15-J14)*$D$4 -> 0 | K17: =(K16-J16)/(K15-K14)*$D$4 -> 0 | L17: =(L16-K16)/(L15-L14)*$D$4 -> 0 | M17: =(M16-L16)/(M15-M14)*$D$4 -> 0 | ... O17: =(O16-N16)/(O15-O14)*$D$4 -> 0
C18: Annual Lease-Up | E18: =E17*12 -> 0 | F18: =F17*12 -> 0 | G18: =G17*12 -> 0 | H18: =H17*12 -> 0 | I18: =I17*12 -> 0 | J18: =J17*12 -> 0 | K18: =K17*12 -> 0 | L18: =L17*12 -> 0 | ... O18: =O17*12 -> 0
C19: Avg Units/Month | E19: =E17/$D$5 -> #DIV/0! | F19: =F17/$D$5 -> #DIV/0! | G19: =G17/$D$5 -> #DIV/0! | H19: =H17/$D$5 -> #DIV/0! | I19: =I17/$D$5 -> #DIV/0! | J19: =J17/$D$5 -> #DIV/0! | K19: =K17/$D$5 -> #DIV/0! | L19: =L17/$D$5 -> #DIV/0! | ... O19: =O17/$D$5 -> #DIV/0!
C21: Revenue Assumptions | E21: 1 | F21: =E21+1 -> 2 | G21: =F21+1 -> 3 | H21: =G21+1 -> 4 | I21: =H21+1 -> 5 | J21: =I21+1 -> 6 | K21: =J21+1 -> 7 | L21: =K21+1 -> 8 | M21: =L21+1 -> 9 | ... O21: =N21+1 -> 11
C22: Discount (recurring) | E22: =-A212 -> 0 | F22: 0.3 | G22: 0.25 | H22: 0.2 | I22: 0.2 | J22: 0.15 | K22: 0.12 | L22: 0.1 | M22: 0.1 | N22: 0.1 | O22: 0.1
C25: Occupancy Growth | E25: {=IF(AND(E$28>=$D$9,E$28<=$D$10),INDEX($E$19:$O$19,,MATCH(E$27,$E$13:$O$13,0)),0)*$D$5/$D$4} -> #DIV/0! | F25: {=IF(AND(F$28>=$D$9,F$28<=$D$10),INDEX($E$19:$O$19,,MATCH(F$27,$E$13:$O$13,0)),0)*$D$5/$D$4} -> #DIV/0! | G25: {=IF(AND(G$28>=$D$9,G$28<=$D$10),INDEX($E$19:$O$19,,MATCH(G$27,$E$13:$O$13,0)),0)*$D$5/$D$4} -> #DIV/0! | H25: {=IF(AND(H$28>=$D$9,H$28<=$D$10),INDEX($E$19:$O$19,,MATCH(H$27,$E$13:$O$13,0)),0)*$D$5/$D$4} -> #DIV/0! | I25: {=IF(AND(I$28>=$D$9,I$28<=$D$10),INDEX($E$19:$O$19,,MATCH(I$27,$E$13:$O$13,0)),0)*$D$5/$D$4} -> #DIV/0! | J25: {=IF(AND(J$28>=$D$9,J$28<=$D$10),INDEX($E$19:$O$19,,MATCH(J$27,$E$13:$O$13,0)),0)*$D$5/$D$4} -> #DIV/0! | K25: {=IF(AND(K$28>=$D$9,K$28<=$D$10),INDEX($E$19:$O$19,,MATCH(K$27,$E$13:$O$13,0)),0)*$D$5/$D$4} -> #DIV/0! | L25: {=IF(AND(L$28>=$D$9,L$28<=$D$10),INDEX($E$19:$O$19,,MATCH(L$27,$E$13:$O$13,0)),0)*$D$5/$D$4} -> #DIV/0! | ... EF25: {=IF(AND(EF$28>=$D$9,EF$28<=$D$10),INDEX($E$19:$O$19,,MATCH(EF$27,$E$13:$O$13,0)),0)*$D$5/$D$4} -> #DIV/0!
C26: Year End Occ | E26: =E25 -> #DIV/0! | F26: =F25+E26 -> #DIV/0! | G26: =G25+F26 -> #DIV/0! | H26: =H25+G26 -> #DIV/0! | I26: =I25+H26 -> #DIV/0! | J26: =J25+I26 -> #DIV/0! | K26: =K25+J26 -> #DIV/0! | L26: =L25+K26 -> #DIV/0! | M26: =M25+L26 -> #DIV/0! | ... EF26: =EF25+EE26 -> #DIV/0!
C27: Year | E27: =ROUNDUP(E28/12,0) -> 1 | F27: =ROUNDUP(F28/12,0) -> 1 | G27: =ROUNDUP(G28/12,0) -> 1 | H27: =ROUNDUP(H28/12,0) -> 1 | I27: =ROUNDUP(I28/12,0) -> 1 | J27: =ROUNDUP(J28/12,0) -> 1 | K27: =ROUNDUP(K28/12,0) -> 1 | L27: =ROUNDUP(L28/12,0) -> 1 | ... EF27: =ROUNDUP(EF28/12,0) -> 11
C28: Month | E28: 1 | F28: =E28+1 -> 2 | G28: =F28+1 -> 3 | H28: =G28+1 -> 4 | I28: =H28+1 -> 5 | J28: =I28+1 -> 6 | K28: =J28+1 -> 7 | L28: =K28+1 -> 8 | M28: =L28+1 -> 9 | ... EF28: =EE28+1 -> 132
C29: Revenue
C30: GPR | E30: {=INDEX(UW!$E$613:$EF$613,,MATCH(E28,UW!$E$612:$EF$612,0))/UW!$D$21*$D$4} -> #DIV/0! | F30: {=INDEX(UW!$E$613:$EF$613,,MATCH(F28,UW!$E$612:$EF$612,0))/UW!$D$21*$D$4} -> #DIV/0! | G30: {=INDEX(UW!$E$613:$EF$613,,MATCH(G28,UW!$E$612:$EF$612,0))/UW!$D$21*$D$4} -> #DIV/0! | H30: {=INDEX(UW!$E$613:$EF$613,,MATCH(H28,UW!$E$612:$EF$612,0))/UW!$D$21*$D$4} -> #DIV/0! | I30: {=INDEX(UW!$E$613:$EF$613,,MATCH(I28,UW!$E$612:$EF$612,0))/UW!$D$21*$D$4} -> #DIV/0! | J30: {=INDEX(UW!$E$613:$EF$613,,MATCH(J28,UW!$E$612:$EF$612,0))/UW!$D$21*$D$4} -> #DIV/0! | K30: {=INDEX(UW!$E$613:$EF$613,,MATCH(K28,UW!$E$612:$EF$612,0))/UW!$D$21*$D$4} -> #DIV/0! | L30: {=INDEX(UW!$E$613:$EF$613,,MATCH(L28,UW!$E$612:$EF$612,0))/UW!$D$21*$D$4} -> #DIV/0! | ... EF30: {=INDEX(UW!$E$613:$EF$613,,MATCH(EF28,UW!$E$612:$EF$612,0))/UW!$D$21*$D$4} -> #DIV/0!
C31: Vacancy | E31: =-IF(E$28<$D$9,E$30,(1-E$26)*E$30) -> #DIV/0! | F31: =-IF(F$28<$D$9,F$30,(1-F$26)*F$30) -> #DIV/0! | G31: =-IF(G$28<$D$9,G$30,(1-G$26)*G$30) -> #DIV/0! | H31: =-IF(H$28<$D$9,H$30,(1-H$26)*H$30) -> #DIV/0! | I31: =-IF(I$28<$D$9,I$30,(1-I$26)*I$30) -> #DIV/0! | J31: =-IF(J$28<$D$9,J$30,(1-J$26)*J$30) -> #DIV/0! | K31: =-IF(K$28<$D$9,K$30,(1-K$26)*K$30) -> #DIV/0! | L31: =-IF(L$28<$D$9,L$30,(1-L$26)*L$30) -> #DIV/0! | ... EF31: =-IF(EF$28<$D$9,EF$30,(1-EF$26)*EF$30) -> #DIV/0!
C32: Gross Rental Income | E32: =SUM(E30:E31) -> #DIV/0! | F32: =SUM(F30:F31) -> #DIV/0! | G32: =SUM(G30:G31) -> #DIV/0! | H32: =SUM(H30:H31) -> #DIV/0! | I32: =SUM(I30:I31) -> #DIV/0! | J32: =SUM(J30:J31) -> #DIV/0! | K32: =SUM(K30:K31) -> #DIV/0! | L32: =SUM(L30:L31) -> #DIV/0! | ... EF32: =SUM(EF30:EF31) -> #DIV/0!
C33: Discount (Recurring) | E33: =-E32*SUMIF($E$21:$O$21,E$27,$E$22:$O$22) -> #DIV/0! | F33: =-F32*SUMIF($E$21:$O$21,F$27,$E$22:$O$22) -> #DIV/0! | G33: =-G32*SUMIF($E$21:$O$21,G$27,$E$22:$O$22) -> #DIV/0! | H33: =-H32*SUMIF($E$21:$O$21,H$27,$E$22:$O$22) -> #DIV/0! | I33: =-I32*SUMIF($E$21:$O$21,I$27,$E$22:$O$22) -> #DIV/0! | J33: =-J32*SUMIF($E$21:$O$21,J$27,$E$22:$O$22) -> #DIV/0! | K33: =-K32*SUMIF($E$21:$O$21,K$27,$E$22:$O$22) -> #DIV/0! | L33: =-L32*SUMIF($E$21:$O$21,L$27,$E$22:$O$22) -> #DIV/0! | ... EF33: =-EF32*SUMIF($E$21:$O$21,EF$27,$E$22:$O$22) -> #DIV/0!
C34: Net Rental Income (Yield | E34: =SUM(E32:E33) -> #DIV/0! | F34: =SUM(F32:F33) -> #DIV/0! | G34: =SUM(G32:G33) -> #DIV/0! | H34: =SUM(H32:H33) -> #DIV/0! | I34: =SUM(I32:I33) -> #DIV/0! | J34: =SUM(J32:J33) -> #DIV/0! | K34: =SUM(K32:K33) -> #DIV/0! | L34: =SUM(L32:L33) -> #DIV/0! | ... EF34: =SUM(EF32:EF33) -> #DIV/0!
C35: Net Yield | E35: =IFERROR(E34/($D$4*E26)*12,"-") -> - | F35: =IFERROR(F34/($D$4*F26)*12,"-") -> - | G35: =IFERROR(G34/($D$4*G26)*12,"-") -> - | H35: =IFERROR(H34/($D$4*H26)*12,"-") -> - | I35: =IFERROR(I34/($D$4*I26)*12,"-") -> - | J35: =IFERROR(J34/($D$4*J26)*12,"-") -> - | K35: =IFERROR(K34/($D$4*K26)*12,"-") -> - | L35: =IFERROR(L34/($D$4*L26)*12,"-") -> - | ... EF35: =IFERROR(EF34/($D$4*EF26)*12,"-") -> -

Sheet Store Budget

Sheet UW
C1: Proforma_Annual | D1: Expense_Details | E1: Debt | F1: Dev_Budget | G1: IFS
C2: Baseline | D2: Proforma_Monthly | E2: Unit_Mix | F2: Sensitivity
B4: Dashboard
C6: Property Description | I6: Purchase Price | M6: Cap Rate | P6: Stamp Duty Calculator
C7: Property Name | F7: Location (scale: 1-5) | J7: Amount | K7: =IF(D13='Model Inputs & Calcs'!B17,"Per Hectare","Per SM") -> Per SM | L7: =IF(D13='Model Inputs & Calcs'!B17,"Per SM","Per NRSM") -> Per NRSM | M7: Seller | N7: Baseline | P7: What State Is The Property? | Q7: QLD
C8: Street Address | F8: Visibility (scale: 1-5) | I8: Asking Price | K8: =IF($D$13='Model Inputs & Calcs'!$B$17,J8/$D$12,J8/$D$20) -> #DIV/0! | L8: =IF($D$13='Model Inputs & Calcs'!$B$17,$J$8/$E$12,J8/$D$21) -> #DIV/0! | M8: =IFERROR($H$550/$J$8,"NA") -> NA | N8: =IFERROR($D$550/$J$8,"NA") -> NA | P8: QLD | Q8: =IF($Q$15="Yes",38025+0.0575*(UW!J9-1000000),(38025+0.0575*(UW!J9*1.1-1000000))) -> -19475
C9: City | F9: Curb Appeal (scale: 1-5) | I9: Offer Price | K9: =IF($D$13='Model Inputs & Calcs'!$B$17,J9/$D$12,J9/$D$20) -> #DIV/0! | L9: =IF($D$13='Model Inputs & Calcs'!$B$17,$J$9/$E$12,J9/$D$21) -> #DIV/0! | M9: =$H$550/J9 -> #DIV/0! | N9: =$D$550/$J$9 -> #DIV/0! | P9: NSW | Q9: =IF($Q$15="Yes",40490+0.055*(UW!J9-1000000),40490+0.055*(UW!J9*1.1-1000000)) -> -14510
C10: State, Postal | F10: Access (scale: 1-5) | P10: VIC | Q10: =IF($Q$15="Yes",0.055*UW!J9,0.055*UW!J9*1.1) -> 0
C11: Parcel # | F11: # of Buildings | I11: Projected Closing Date | K11: Absentee Owner Surcharge | L11: Sources | N11: Per NRSM | P11: SA | Q11: =IF($Q$15="Yes",21330+0.055*(UW!J9-500000),21330+0.055*(UW!J9-500000)*1.1) -> -8920
C12: Parcel Size | D12: 0 | E12: =D12*10000 -> 0 | F12: # of Stories | I12: 46112 | K12: Yes | L12: Initial Debt | M12: =E47 -> #DIV/0! | N12: =M12/$D$21 -> #DIV/0! | O12: =M12/M14 -> #DIV/0! | P12: WA | Q12: =IF($Q$15="Yes",19665+0.0515*(UW!J9-500000),19665+0.0515*(UW!J9-500000)*1.1) -> -8660
C13: Investment Type | D13: Existing | F13: # of Elevators | L13: Equity | M13: =M31-M12 -> #DIV/0! | N13: =M13/$D$21 -> #DIV/0! | O13: =M13/M14 -> #DIV/0! | P13: NT | Q13: TBD
C14: Broker | F14: Broker Name | I14: Metrics | K14: Fees | L14: Total Sources: | M14: =SUM(M12:M13) -> #DIV/0! | N14: =M14/$D$21 -> #DIV/0! | P14: TAS | Q14: =IF($Q$15="Yes",27810+0.045*(UW!J9-725000),27810+0.045*(UW!J9-725000)*1.1) -> -8077.5
C15: Zoning | F15: Flood Zone | I15: IRR (Post fees & taxes) | J15: =XIRR($D$756:$EF$756,$D$607:$EF$607) -> #DIV/0! | K15: Yes | L15: Uses | N15: Per NRSM | P15: Going Concern? | Q15: No
C16: Traffic Count | F16: Traffic Count Street | I16: Equity Multiple | J16: =SUM(E755:EF755)/Total_Equity -> #DIV/0! | L16: Purchase Price | M16: =J9 -> 0 | N16: =M16/$D$21 -> #DIV/0!
C17: Renovated | F17: Software | I17: Stab. YoC - Untrended | J17: =Sheet1!C10/UW!M14 -> #DIV/0! | K17: FOS incl. in valuation | L17: Acquisition Fee | M17: =J51*J9 -> 0 | N17: =M17/$D$21 -> #DIV/0! | P17: Unlevered Equity Loaded
C18: Manager Apartment? | F18: Year Built | I18: Stab. YoC - Untrended (Norm.) | J18: =Sheet1!C13/UW!M14 -> #DIV/0! | K18: No | L18: Loan Fees | M18: =M12*(E49+E50) -> #DIV/0! | N18: =M18/$D$21 -> #DIV/0! | P18: Total Uses | Q18: =UW!M31 -> #DIV/0!
C19: Rental Summary | I19: Stab. YoC - Trended | J19: =(OFFSET(D714,,J25)*12)/M14 -> #DIV/0! | L19: GST Required | M19: 0 | N19: =M19/$D$21 -> #DIV/0! | P19: Minus Interest Reserve | Q19: =-SUM(UW!E411:O411) -> #DIV/0!
C20: Gross SM (Entire Facility) | D20: ='Unit Mix Generator'!P19 -> 0 | E20: =D21+D28+G28+G21+D34 -> 0 | F20: Office? | G20: No | I20: Stab. YoC - Trended (Norm.) | J20: =((OFFSET(D714,,J25)+OFFSET(D709,,J25)+OFFSET(D710,,J25))*12)/M14 -> #DIV/0! | K20: ManCo | L20: Establishment Costs | M20: =D557 -> 0 | N20: =M20/$D$21 -> #DIV/0! | P20: Minus Loan Fees | Q20: =-UW!M18 -> #DIV/0!
C21: Net Rentable SM (Storage Only) | D21: =IF($C$444='Model Inputs & Calcs'!$B$5,$C$451,'Comps & Unit Mix'!AW328) -> 0 | E21: =E20/D20 -> #DIV/0! | F21: Net Rentable SM (Office) | G21: ='Comps & Unit Mix'!AW426 -> 0 | I21: Exit YoC | J21: =OFFSET(D714,,J36)*12/M14 -> #DIV/0! | K21: No | L21: Distribution Costs | M21: =D558 -> 0 | N21: =M21/$D$21 -> #DIV/0! | P21: Minus Assump/Prepay/Defease | Q21: =-UW!M19 -> 0
C22: # Storage Units | D22: =IF($C$444='Model Inputs & Calcs'!$B$5,C452,'Comps & Unit Mix'!AV328) -> 0 | E22: =(D25*D21+D31*D28)/E20 -> #DIV/0! | F22: # Office Units | G22: ='Comps & Unit Mix'!AV426 -> 0 | I22: Exit YoC (Norm.) | J22: =(OFFSET(D714,,J36)+OFFSET(D709,,J25)+OFFSET(D710,,J25))*12/M14 -> #DIV/0! | L22: Due Diligence | M22: =D559 -> 100000 | N22: =M22/$D$21 -> #DIV/0! | P22: Equity Required | Q22: =SUM(Q18:Q21) -> #DIV/0!
C23: Average Unit Size (Storage) | D23: =D21/D22 -> #DIV/0! | F23: Average Office Size | G23: =G21/G22 -> #DIV/0! | I23: Exit Cap Rate | J23: =Val!E7 -> 0 | L23: Conversion Costs | M23: =D560 -> 0 | N23: =M23/$D$21 -> #DIV/0! | P23: Unlevered Equity Loaded | Q23: =Q22 -> #DIV/0!
C24: Average Monthly Lease Up (m2) | D24: =SUM(E92:O92)/(G95-E95) -> 0 | F24: Term? | G24: Month to Month | I24: Stab. Occupancy | J24: =MAX(E97:O97) -> 0 | L24: Capex | M24: =D561 -> 0
C25: Occupancy | D25: =IF($C$444='Model Inputs & Calcs'!$B$5,$C$450,IF($C$444='Model Inputs & Calcs'!$B$6,$D$218,"")) -> 0 | E25: =D219 -> #DIV/0! | F25: Occupancy | G25: ='Comps & Unit Mix'!AR426/'Comps & Unit Mix'!AW426 -> #DIV/0! | I25: Stab. Month | J25: =IF(E97=J24,E96,IF(F97=J24,F96,IF(G97=J24,G96,IF(H97=J24,H96,IF(I97=J24,I96))))) -> 12 | L25: Transer/Stamp Duty/GST | M25: =INDEX(UW!Q8:Q14,(MATCH(UW!Q7,UW!P8:P14,0))) -> -19475 | N25: =M25/$D$21 -> #DIV/0! | P25: Remaining Equity Contribution after Refi 1
C26: Asking Rents | D26: =D455/D21 -> #DIV/0! | E26: =IFERROR(D461/SUM('Comps & Unit Mix'!AR209:AR326),"-") -> - | F26: Asking Rents (Office) | G26: ='Comps & Unit Mix'!BE427 -> 0 | L26: Constr/OpEx/Intrst (Equity) | M26: =SUM($E$748:$EF$748)-M30-M28-M27 -> #DIV/0! | N26: =M26/$D$21 -> #DIV/0! | P26: Return (Addtl Contr) of Equity | Q26: =C57+M29 -> #DIV/0!
C27: RV/Parking? | D27: No | F27: Warehouse? | G27: No | L27: Const Holdback (Debt) | M27: =E43 -> 0 | N27: =M27/$D$21 -> #DIV/0! | P27: Year Returned | Q27: =CEILING(UW!E63,12)/12 -> 3 | R27: =E63 -> 33
C28: RV/Parking NLA | D28: ='Comps & Unit Mix'!AW439 -> 0 | E28: 0% on Exp. Start | F28: Warehouse NLA | G28: ='Workstore Sales'!C6 -> 0 | I28: Sale | L28: Op Ex Holdback (Debt) | M28: =E44 -> 0 | N28: =M28/$D$21 -> #DIV/0! | P28: Remaining Loaded Equity | Q28: =UW!M35-Q26 -> #DIV/0!
C29: # Parking Spaces | D29: ='Comps & Unit Mix'!AV439 -> 0 | F29: # Warehouse Units | G29: ='Workstore Sales'!C2 -> 15 | I29: Gross Sale | J29: =IF($J$39='Model Inputs & Calcs'!$C$5,OFFSET(Val!$C$99,,UW!J36),OFFSET(Val!$C$98,,UW!$J$36)) -> 0 | L29: Interest Reserve (Equity) | M29: =E45 -> 0 | N29: =M29/$D$21 -> #DIV/0!
C30: Average Parking Size | D30: =IFERROR(D28/D29,0) -> 0 | F30: Average Warehouse Size | G30: ='Workstore Sales'!C5 -> 0 | I30: Sales Costs | J30: =-J29*SUM(J37:J38) -> 0 | L30: Interest Reserve (Debt) | M30: =E46 -> #DIV/0! | N30: =M30/$D$21 -> #DIV/0! | P30: Remaining Equity Contribution after Refi 2
C31: Occupancy | D31: =IFERROR('Comps & Unit Mix'!AY440,"0") -> 0 | E31: =D624 -> 0 | F31: Occupancy | G31: =IFERROR('Comps & Unit Mix'!AR414/'Comps & Unit Mix'!AW414,0) -> 0 | I31: Net Sale | J31: =SUM(J29:J30) -> 0 | L31: Total Uses: | M31: =SUM(M16:M30) -> #DIV/0! | N31: =M31/$D$21 -> #DIV/0! | P31: Return (Addtl Contr) of Equity | Q31: =UW!C64 -> 835.53546
C32: Asking Rents (RV/Parking) | D32: =IFERROR('Comps & Unit Mix'!BE440,"0") -> 0 | F32: Sale Rate (Warehouse) | G32: ='Workstore Sales'!C3 -> 5300 | I32: Loan Repayment | J32: =-HLOOKUP($J$36,$E$855:$DT$860,6,FALSE) -> 835.53546 | N32: Per NSRM | P32: Year Returned | Q32: =CEILING(UW!F63,12)/12 -> 4 | R32: =F63 -> 48
C33: Expansion? | D33: No | F33: #Expansion Units | G33: =IF(D33="Yes",'Comps & Unit Mix'!AV399,0) -> 0 | I33: Return of Equity | J33: =-Total_Equity -> #DIV/0! | L33: Equity | M33: =M13 -> #DIV/0! | N33: =M33/$D$21 -> #DIV/0! | P33: Remaining Loaded Equity | Q33: =Q28-Q31 -> #DIV/0!
C34: Expansion NLA | D34: =IF(D33="Yes",'Comps & Unit Mix'!AW399,0) -> 0 | E34: ='Comps & Unit Mix'!AY400 -> 0 | F34: Average Expansion Size | G34: =D34/G33 -> #DIV/0! | I34: Net Proceeds | J34: =SUM(J31:J33) -> #DIV/0!
C35: Notes: | I35: Disposition Assumptions | L35: Equity | M35: =SUM(M33:M34) -> #DIV/0! | N35: =M35/$D$21 -> #DIV/0! | P35: Site Cover | Q35: =('Unit Mix Generator'!P14+D28+'Workstore Sales'!C33)/UW!E12 -> #DIV/0!
I36: Sale Year | J36: {=OFFSET(Val!C15,,(MATCH('Model Inputs & Calcs'!C12,Val!$D$16:$EE$16,0)),,)} -> 48 | L36: Debt | M36: =M12 -> #DIV/0! | N36: =M36/$D$21 -> #DIV/0! | P36: WACC | Q36: =((M36/M37)*E56)+((M35/M37)*#REF!) -> #DIV/0!
I37: Sales Broker Commission | J37: 0.01 | L37: Total Consideration: | M37: =SUM(M35:M36) -> #DIV/0! | N37: =M37/$D$21 -> #DIV/0!
I38: Cost of Sales | J38: 0.0025 | P38: =C770 -> Perfomance Fee Calculations (Paid at Sale)
I39: Sale Price Val Option | J39: Cap Rate | L39: Construction | P39: =C771 -> NPV | Q39: =D771 -> #DIV/0!
C40: Debt | E40: Initial Loan | F40: Refinance Loan 1 | G40: Refinance Loan 2 | I40: Hurdle Rate | J40: 0.1 | L40: Construction (Debt) | M40: =M27 -> 0 | N40: =M40/$D$21 -> #DIV/0! | P40: =C772 -> Duration of Investment | Q40: =D772 -> 4.0027397
D41: Debt Type | E41: Permanent | F41: Permanent | G41: Permanent | I41: Hurdle Rate Reference | L41: Construction (Equity) | M41: =M42-M40 -> 0 | N41: =M41/$D$21 -> #DIV/0! | P41: =C773 -> Total Realisation Value | Q41: =D773 -> #DIV/0!
C42: Holdback Structure | D42: Initial Loan Amount | E42: =UW!J9*UW!C49 -> 0 | F42: =IF(C52="yes",C54*C55,0) -> -835.53546 | G42: =IF(C59="yes",C61*C62,0) -> 0 | I42: A+ Stabilized = 8% | J42: Development = 15% | L42: Ttl Construction Cost | M42: =IF(OR($D$13='Model Inputs & Calcs'!$B$17,$D$13='Model Inputs & Calcs'!$B$16),'Dev Bdgt'!E57,0) -> 0 | N42: =M42/$D$21 -> #DIV/0! | P42: =C774 -> Hurdle Realisation Value | Q42: =D774 -> #DIV/0!
...

Sheet Sheet1
B2: Stabilised Yield on Cost - Untrended
B3: NLA | C3: =UW!D21 -> 0
B4: Day 1 Operating Rent | C4: =OFFSET(UW!D613,,IF(UW!$E$97>0,UW!$E$95,IF(UW!$F$97>0,UW!$F$95,IF(UW!$G$97>0,UW!$G$95))))/UW!$D$21*12 -> #DIV/0!
B5: Stabilised Occupancy | C5: =UW!$J$24 -> 0
B6: Stabilised Discount Rate | C6: 0.04
B7: Income | C7: =C3*C4*C5*(1-C6) -> #DIV/0!
B8: Other Income | C8: =C7*0.004 -> #DIV/0!
B9: Total Expenses | C9: =UW!D391 -> 375238.2
B10: NOI | C10: =C7+C8-C9 -> #DIV/0!
B12: Normalised Costs | C12: =UW!D388+UW!D389 -> 149700
B13: NOI | C13: =C10+C12 -> #DIV/0!

Sheet Sensitivity Analysis
B2: Sensitivty Analysis
C5: Land Rate | D5: 700 | E5: 750 | F5: 800 | G5: 850 | H5: 900
C6: Asking rate | D6: $341/m2 | E6: $345/m2 | F6: $349/m2 | G6: $353/m2 | H6: $357/m2
C7: IRR | D7: 0.1503 | E7: 0.1502 | F7: 0.1502 | G7: 0.1502 | H7: 0.15

Sheet Submarket Analysis
B2: Deal Name | C2: =UW!D7 -> 0
B3: Address | C3: =UW!D8 -> 0
B4: State | C4: =UW!D10 -> 0
B5: Land Area | C5: =UW!E12 -> 0
B6: GFA | C6: =UW!D20 -> 0
B7: NLA | C7: =UW!D21 -> 0
B9: Geographic Market Area | D9: 8
B11: Stores | D11: Address | G11: NLA | H11: Distance (km) | I11: Direction | J11: Drive Time (Mins) | L11: Development Pipeline | P11: Address | T11: NLA | U11: Distance (km) | V11: Direction | W11: Drive Time (Mins)
L16: Total | T16: =SUM(T12:T15) -> 0
B30: Total | G30: =SUM(G12:G29) -> 0
B34: Supply Summary
D35: Radius (km) | G35: Drive Time (mins)
D36: 3 | E36: 5 | F36: =D9 -> 8 | G36: 3 | H36: 5 | I36: 10
B37: Existing Supply | D37: =SUMIF($H$12:$H$29,"<="&D$36,$G$12:$G$29) -> 0 | E37: =SUMIF($H$12:$H$29,"<="&E$36,$G$12:$G$29) -> 0 | F37: =SUMIF($H$12:$H$29,"<="&F$36,$G$12:$G$29) -> 0 | G37: =SUMIF($J$12:$J$29,"<="&G$36,$G$12:$G$29) -> 0 | H37: =SUMIF($J$12:$J$29,"<="&H$36,$G$12:$G$29) -> 0 | I37: =SUMIF($J$12:$J$29,"<="&I$36,$G$12:$G$29) -> 0
B38: Population
B39: Supply/capita | D39: =IFERROR(D37/D38,0) -> 0 | E39: =IFERROR(E37/E38,0) -> 0 | F39: =IFERROR(F37/F38,0) -> 0 | G39: =IFERROR(G37/G38,0) -> 0 | H39: =IFERROR(H37/H38,0) -> 0 | I39: =IFERROR(I37/I38,0) -> 0
B40: Add: Subject Supply | D40: =D37+$C$7 -> 0 | E40: =E37+$C$7 -> 0 | F40: =F37+$C$7 -> 0 | G40: =G37+$C$7 -> 0 | H40: =H37+$C$7 -> 0 | I40: =I37+$C$7 -> 0
B41: Supply/capita | D41: =IFERROR(D40/D38,0) -> 0 | E41: =IFERROR(E40/E38,0) -> 0 | F41: =IFERROR(F40/F38,0) -> 0 | G41: =IFERROR(G40/G38,0) -> 0 | H41: =IFERROR(H40/H38,0) -> 0 | I41: =IFERROR(I40/I38,0) -> 0
B42: Add: Pipeline Supply | D42: =SUMIF($U$12:$U$15,"<="&D$36,$T$12:$T$15)+D40 -> 0 | E42: =SUMIF($U$12:$U$15,"<="&E$36,$T$12:$T$15)+E40 -> 0 | F42: =SUMIF($U$12:$U$15,"<="&F$36,$T$12:$T$15)+F40 -> 0 | G42: =SUMIF($W$12:$W$15,"<="&G$36,$T$12:$T$15)+G40 -> 0 | H42: =SUMIF($W$12:$W$15,"<="&H$36,$T$12:$T$15)+H40 -> 0 | I42: =SUMIF($W$12:$W$15,"<="&I$36,$T$12:$T$15)+I40 -> 0
B43: Supply/capita | D43: =IFERROR(D42/D38,0) -> 0 | E43: =IFERROR(E42/E38,0) -> 0 | F43: =IFERROR(F42/F38,0) -> 0 | G43: =IFERROR(G42/G38,0) -> 0 | H43: =IFERROR(H42/H38,0) -> 0 | I43: =IFERROR(I42/I38,0) -> 0
B44: StoreLocal Pacific Pines | D44: 0.13 | E44: 0.47 | F44: 0.51 | G44: 16.29 | H44: 0.73 | I44: 0.59
B45: StoreLocal Pimpama | D45: 0.41 | E45: 0.73 | F45: 0.45 | G45: 4.01 | H45: 1.81 | I45: 1.42
B46: StoreLocal Berrinba | D46: 0.4 | E46: 0.44 | F46: 0.33 | G46: 1.64 | H46: 0.7 | I46: 0.45
B47: StoreLocal Port Kennedy | D47: 1.61 | E47: 0.7 | F47: 0.3 | G47: 9.76 | H47: 1.49 | I47: 0.44
B49: Demand Table | K49: Over/(Under) Supply
D50: Radius (km) | G50: Drive Time (mins) | M50: Radius (km) | P50: Drive Time (mins)
B51: sqm/Demand/Person | D51: =D$36 -> 3 | E51: =E$36 -> 5 | F51: =F$36 -> 8 | G51: =G$36 -> 3 | H51: =H$36 -> 5 | I51: =I$36 -> 10 | K51: sqm/Demand/Person | M51: =D$36 -> 3 | N51: =E$36 -> 5 | O51: =F$36 -> 8 | P51: =G$36 -> 3 | Q51: =H$36 -> 5 | R51: =I$36 -> 10
B52: 0.1 | D52: =$B52*D$38 -> 0 | E52: =$B52*E$38 -> 0 | F52: =$B52*F$38 -> 0 | G52: =$B52*G$38 -> 0 | H52: =$B52*H$38 -> 0 | I52: =$B52*I$38 -> 0 | K52: 0.1 | M52: =D$42-D52 -> 0 | N52: =E$42-E52 -> 0 | O52: =F$42-F52 -> 0 | P52: =G$42-G52 -> 0 | Q52: =H$42-H52 -> 0 | R52: =I$42-I52 -> 0
B53: 0.2 | D53: =$B53*D$38 -> 0 | E53: =$B53*E$38 -> 0 | F53: =$B53*F$38 -> 0 | G53: =$B53*G$38 -> 0 | H53: =$B53*H$38 -> 0 | I53: =$B53*I$38 -> 0 | K53: 0.2 | M53: =D$42-D53 -> 0 | N53: =E$42-E53 -> 0 | O53: =F$42-F53 -> 0 | P53: =G$42-G53 -> 0 | Q53: =H$42-H53 -> 0 | R53: =I$42-I53 -> 0
B54: 0.3 | D54: =$B54*D$38 -> 0 | E54: =$B54*E$38 -> 0 | F54: =$B54*F$38 -> 0 | G54: =$B54*G$38 -> 0 | H54: =$B54*H$38 -> 0 | I54: =$B54*I$38 -> 0 | K54: 0.3 | M54: =D$42-D54 -> 0 | N54: =E$42-E54 -> 0 | O54: =F$42-F54 -> 0 | P54: =G$42-G54 -> 0 | Q54: =H$42-H54 -> 0 | R54: =I$42-I54 -> 0
B55: 0.4 | D55: =$B55*D$38 -> 0 | E55: =$B55*E$38 -> 0 | F55: =$B55*F$38 -> 0 | G55: =$B55*G$38 -> 0 | H55: =$B55*H$38 -> 0 | I55: =$B55*I$38 -> 0 | K55: 0.4 | M55: =D$42-D55 -> 0 | N55: =E$42-E55 -> 0 | O55: =F$42-F55 -> 0 | P55: =G$42-G55 -> 0 | Q55: =H$42-H55 -> 0 | R55: =I$42-I55 -> 0
B56: 0.5 | D56: =$B56*D$38 -> 0 | E56: =$B56*E$38 -> 0 | F56: =$B56*F$38 -> 0 | G56: =$B56*G$38 -> 0 | H56: =$B56*H$38 -> 0 | I56: =$B56*I$38 -> 0 | K56: 0.5 | M56: =D$42-D56 -> 0 | N56: =E$42-E56 -> 0 | O56: =F$42-F56 -> 0 | P56: =G$42-G56 -> 0 | Q56: =H$42-H56 -> 0 | R56: =I$42-I56 -> 0
B57: 0.6 | D57: =$B57*D$38 -> 0 | E57: =$B57*E$38 -> 0 | F57: =$B57*F$38 -> 0 | G57: =$B57*G$38 -> 0 | H57: =$B57*H$38 -> 0 | I57: =$B57*I$38 -> 0 | K57: 0.6 | M57: =D$42-D57 -> 0 | N57: =E$42-E57 -> 0 | O57: =F$42-F57 -> 0 | P57: =G$42-G57 -> 0 | Q57: =H$42-H57 -> 0 | R57: =I$42-I57 -> 0
B58: 0.7 | D58: =$B58*D$38 -> 0 | E58: =$B58*E$38 -> 0 | F58: =$B58*F$38 -> 0 | G58: =$B58*G$38 -> 0 | H58: =$B58*H$38 -> 0 | I58: =$B58*I$38 -> 0 | K58: 0.7 | M58: =D$42-D58 -> 0 | N58: =E$42-E58 -> 0 | O58: =F$42-F58 -> 0 | P58: =G$42-G58 -> 0 | Q58: =H$42-H58 -> 0 | R58: =I$42-I58 -> 0
C61: Deomgraphics | D61: =C2 -> 0 | E61: =C4 -> 0 | F61: Variance to State | G61: Australia | H61: Variance to AUS
C62: Avg. No. of People per Household | F62: =D62/E62-1 -> #DIV/0! | G62: 2.5 | H62: =D62/G62-1 -> -1
C63: Median Weekly Household Income | F63: =D63/E63-1 -> #DIV/0! | G63: 1746 | H63: =D63/G63-1 -> -1
C64: Less than $650 (Weekly) | F64: =D64/E64-1 -> #DIV/0! | G64: 0.165 | H64: =D64/G64-1 -> -1
C65: More than $3,000 (Weekly) | F65: =D65/E65-1 -> #DIV/0! | G65: 0.243 | H65: =D65/G65-1 -> -1
C66: Median Monthly Mortgage Repayments | F66: =D66/E66-1 -> #DIV/0! | G66: 1863 | H66: =D66/G66-1 -> -1
...

Sheet Comps & Unit Mix
B1: STORELOCAL xxx MARKET RENT ANALYSIS
B3: 10 | C3: 1 | D3: 3 | E3: 5 | F3: =B3 -> 10 | J3: Competitor:
B4: Total SF: | C4: =SUMIF($N$9:$AS$9,"<="&C3,$N$6:$AS$6)+$G$6 -> 0 | D4: =SUMIF($N$9:$AS$9,"<="&D3,$N$6:$AS$6)+$G$6 -> 0 | E4: =SUMIF($N$9:$AS$9,"<="&E3,$N$6:$AS$6)+G6 -> 0 | F4: =SUMIF($N$9:$AS$9,"<="&F3,$N$6:$AS$6)+$G$6 -> 0 | J4: Address:
B5: Pop: | J5: Occupancy:
B6: SM / Person: | C6: =C4/C5 -> #DIV/0! | D6: =D4/D5 -> #DIV/0! | E6: =E4/E5 -> #DIV/0! | F6: =F4/F5 -> #DIV/0! | G6: =AW268 -> 0 | J6: Size: | N6: =N199 -> 0 | P6: =P199 -> 0 | R6: =R199 -> 0 | T6: =T199 -> 0 | V6: =V199 -> 0 | X6: =X199 -> 0 | Z6: =Z199 -> 0 | AB6: =AB199 -> 0 | AD6: =AD199 -> 0 | AF6: =AF199 -> 0 | AH6: =AH199 -> 0 | AJ6: 0 | AL6: 0 | AN6: 0 | AP6: 0 | AR6: =AR199 -> 0
B7: higher | J7: RV / Boat? : | N7: No | P7: No | R7: No | T7: No | V7: No | X7: Yes | Z7: Yes | AB7: No | AD7: No | AF7: No | AH7: No | AJ7: No | AL7: No | AN7: No | AP7: No | AR7: No
B8: lower | E8: Date created: | F8: <Insert Date> | J8: Direction:
B9: new | E9: Date last updated: | F9: <Insert Date> | J9: Distance:
G10: SELECTED COMPS | I10: RENT COMPS | K10: RENT DISCOUNT | N10: Yes | O10: =N10 -> Yes | P10: Yes | Q10: =P10 -> Yes | R10: Yes | S10: =R10 -> Yes | T10: Yes | U10: =T10 -> Yes | V10: Yes | W10: =V10 -> Yes | X10: No | Y10: =X10 -> No | Z10: No | AB10: No | AC10: =AB10 -> No | AD10: No | AE10: =AD10 -> No | AF10: No | AG10: =AF10 -> No | AH10: No | AI10: =AH10 -> No | AJ10: No | AK10: No | AL10: No | AM10: No | AN10: No | AO10: No | AP10: No | AR10: No | AS10: =AR10 -> No
B11: Size | C11: SM | D11: Floor | E11: Type | F11: CC? | G11: Per SM | H11: Per Unit | I11: Per SM | J11: Per Unit | K11: Per SM | L11: Per Unit | N11: Asking Rate | O11: Discount | P11: Asking Rate | Q11: Discount | R11: Asking Rate | S11: Discount | T11: Asking Rate | U11: Discount | V11: Asking Rate | W11: Discount | X11: Asking Rate | Y11: Discount | Z11: Asking Rate | AA11: Discount | AB11: Asking Rate | AC11: Discount | AD11: Asking Rate | AE11: Discount | AF11: Asking Rate | AG11: Discount | AH11: Asking Rate | AI11: Discount | AJ11: Asking Rate | AK11: Discount | AL11: Asking Rate | AM11: Discount | AN11: Asking Rate | AO11: Discount | AP11: Asking Rate | AQ11: Discount | AR11: Asking Rate | AS11: Discount
B12: 1.5x1.5 | C12: 2.25 | D12: 1 | E12: Drive-up | F12: No | G12: =IFERROR((H12/$C12),"-") -> - | H12: =IFERROR(AVERAGEIFS(N12:AS12,$N$11:$AS$11,"Asking Rate",$N$10:$AS$10,$B$204),"-") -> - | I12: =IFERROR((J12/$C12),"-") -> - | J12: =IFERROR(AVERAGEIF($N$9:$AS$9,"<="&$B$3,N12:AS12),"-") -> - | K12: =IFERROR((L12/$C12),"-") -> - | L12: =IFERROR(AVERAGEIFS(N12:AS12,$N$11:$AS$11,"Discount",$N$10:$AS$10,$B$204),"-") -> -
B13: 1.5x2 | C13: 3 | D13: 1 | E13: Drive-up | F13: No | G13: =IFERROR((H13/$C13),"-") -> - | H13: =IFERROR(AVERAGEIFS(N13:AS13,$N$11:$AS$11,"Asking Rate",$N$10:$AS$10,$B$204),"-") -> - | I13: =IFERROR((J13/$C13),"-") -> - | J13: =IFERROR(AVERAGEIF($N$9:$AS$9,"<="&$B$3,N13:AS13),"-") -> - | K13: =IFERROR((L13/$C13),"-") -> - | L13: =IFERROR(AVERAGEIFS(N13:AS13,$N$11:$AS$11,"Discount",$N$10:$AS$10,$B$204),"-") -> -
B14: 1.2x3 | C14: 3.6 | D14: 1 | E14: Drive-up | F14: No | G14: =IFERROR((H14/$C14),"-") -> - | H14: =IFERROR(AVERAGEIFS(N14:AS14,$N$11:$AS$11,"Asking Rate",$N$10:$AS$10,$B$204),"-") -> - | I14: =IFERROR((J14/$C14),"-") -> - | J14: =IFERROR(AVERAGEIF($N$9:$AS$9,"<="&$B$3,N14:AS14),"-") -> - | K14: =IFERROR((L14/$C14),"-") -> - | L14: =IFERROR(AVERAGEIFS(N14:AS14,$N$11:$AS$11,"Discount",$N$10:$AS$10,$B$204),"-") -> -
B15: 1.4x3 | C15: 4.2 | D15: 1 | E15: Drive-up | F15: No | G15: =IFERROR((H15/$C15),"-") -> - | H15: =IFERROR(AVERAGEIFS(N15:AS15,$N$11:$AS$11,"Asking Rate",$N$10:$AS$10,$B$204),"-") -> - | I15: =IFERROR((J15/$C15),"-") -> - | J15: =IFERROR(AVERAGEIF($N$9:$AS$9,"<="&$B$3,N15:AS15),"-") -> - | K15: =IFERROR((L15/$C15),"-") -> - | L15: =IFERROR(AVERAGEIFS(N15:AS15,$N$11:$AS$11,"Discount",$N$10:$AS$10,$B$204),"-") -> -
B16: 1.5x3 | C16: 4.5 | D16: 1 | E16: Drive-up | F16: No | G16: =IFERROR((H16/$C16),"-") -> - | H16: =IFERROR(AVERAGEIFS(N16:AS16,$N$11:$AS$11,"Asking Rate",$N$10:$AS$10,$B$204),"-") -> - | I16: =IFERROR((J16/$C16),"-") -> - | J16: =IFERROR(AVERAGEIF($N$9:$AS$9,"<="&$B$3,N16:AS16),"-") -> - | K16: =IFERROR((L16/$C16),"-") -> - | L16: =IFERROR(AVERAGEIFS(N16:AS16,$N$11:$AS$11,"Discount",$N$10:$AS$10,$B$204),"-") -> -
B17: 2x3 | C17: 6 | D17: 1 | E17: Drive-up | F17: No | G17: =IFERROR((H17/$C17),"-") -> - | H17: =IFERROR(AVERAGEIFS(N17:AS17,$N$11:$AS$11,"Asking Rate",$N$10:$AS$10,$B$204),"-") -> - | I17: =IFERROR((J17/$C17),"-") -> - | J17: =IFERROR(AVERAGEIF($N$9:$AS$9,"<="&$B$3,N17:AS17),"-") -> - | K17: =IFERROR((L17/$C17),"-") -> - | L17: =IFERROR(AVERAGEIFS(N17:AS17,$N$11:$AS$11,"Discount",$N$10:$AS$10,$B$204),"-") -> -
B18: 1.4x4.5 | C18: 6.3 | D18: 1 | E18: Drive-up | F18: No | G18: =IFERROR((H18/$C18),"-") -> - | H18: =IFERROR(AVERAGEIFS(N18:AS18,$N$11:$AS$11,"Asking Rate",$N$10:$AS$10,$B$204),"-") -> - | I18: =IFERROR((J18/$C18),"-") -> - | J18: =IFERROR(AVERAGEIF($N$9:$AS$9,"<="&$B$3,N18:AS18),"-") -> - | K18: =IFERROR((L18/$C18),"-") -> - | L18: =IFERROR(AVERAGEIFS(N18:AS18,$N$11:$AS$11,"Discount",$N$10:$AS$10,$B$204),"-") -> -
B19: 2.3x3 | C19: 6.9 | D19: 1 | E19: Drive-up | F19: No | G19: =IFERROR((H19/$C19),"-") -> - | H19: =IFERROR(AVERAGEIFS(N19:AS19,$N$11:$AS$11,"Asking Rate",$N$10:$AS$10,$B$204),"-") -> - | I19: =IFERROR((J19/$C19),"-") -> - | J19: =IFERROR(AVERAGEIF($N$9:$AS$9,"<="&$B$3,N19:AS19),"-") -> - | K19: =IFERROR((L19/$C19),"-") -> - | L19: =IFERROR(AVERAGEIFS(N19:AS19,$N$11:$AS$11,"Discount",$N$10:$AS$10,$B$204),"-") -> -
B20: 2.5x3 | C20: 7.5 | D20: 1 | E20: Drive-up | F20: No | G20: =IFERROR((H20/$C20),"-") -> - | H20: =IFERROR(AVERAGEIFS(N20:AS20,$N$11:$AS$11,"Asking Rate",$N$10:$AS$10,$B$204),"-") -> - | I20: =IFERROR((J20/$C20),"-") -> - | J20: =IFERROR(AVERAGEIF($N$9:$AS$9,"<="&$B$3,N20:AS20),"-") -> - | K20: =IFERROR((L20/$C20),"-") -> - | L20: =IFERROR(AVERAGEIFS(N20:AS20,$N$11:$AS$11,"Discount",$N$10:$AS$10,$B$204),"-") -> -
B21: 2x4 | C21: 8 | D21: 1 | E21: Drive-up | F21: No | G21: =IFERROR((H21/$C21),"-") -> - | H21: =IFERROR(AVERAGEIFS(N21:AS21,$N$11:$AS$11,"Asking Rate",$N$10:$AS$10,$B$204),"-") -> - | I21: =IFERROR((J21/$C21),"-") -> - | J21: =IFERROR(AVERAGEIF($N$9:$AS$9,"<="&$B$3,N21:AS21),"-") -> - | K21: =IFERROR((L21/$C21),"-") -> - | L21: =IFERROR(AVERAGEIFS(N21:AS21,$N$11:$AS$11,"Discount",$N$10:$AS$10,$B$204),"-") -> -
B22: 6x1.4 | C22: 8.4 | D22: 1 | E22: Drive-up | F22: No | G22: =IFERROR((H22/$C22),"-") -> - | H22: =IFERROR(AVERAGEIFS(N22:AS22,$N$11:$AS$11,"Asking Rate",$N$10:$AS$10,$B$204),"-") -> - | I22: =IFERROR((J22/$C22),"-") -> - | J22: =IFERROR(AVERAGEIF($N$9:$AS$9,"<="&$B$3,N22:AS22),"-") -> - | K22: =IFERROR((L22/$C22),"-") -> - | L22: =IFERROR(AVERAGEIFS(N22:AS22,$N$11:$AS$11,"Discount",$N$10:$AS$10,$B$204),"-") -> -
B23: 3x3 | C23: 9 | D23: 1 | E23: Drive-up | F23: No | G23: =IFERROR((H23/$C23),"-") -> - | H23: =IFERROR(AVERAGEIFS(N23:AS23,$N$11:$AS$11,"Asking Rate",$N$10:$AS$10,$B$204),"-") -> - | I23: =IFERROR((J23/$C23),"-") -> - | J23: =IFERROR(AVERAGEIF($N$9:$AS$9,"<="&$B$3,N23:AS23),"-") -> - | K23: =IFERROR((L23/$C23),"-") -> - | L23: =IFERROR(AVERAGEIFS(N23:AS23,$N$11:$AS$11,"Discount",$N$10:$AS$10,$B$204),"-") -> -
B24: 3x3.5 | C24: 10.5 | D24: 1 | E24: Drive-up | F24: No | G24: =IFERROR((H24/$C24),"-") -> - | H24: =IFERROR(AVERAGEIFS(N24:AS24,$N$11:$AS$11,"Asking Rate",$N$10:$AS$10,$B$204),"-") -> - | I24: =IFERROR((J24/$C24),"-") -> - | J24: =IFERROR(AVERAGEIF($N$9:$AS$9,"<="&$B$3,N24:AS24),"-") -> - | K24: =IFERROR((L24/$C24),"-") -> - | L24: =IFERROR(AVERAGEIFS(N24:AS24,$N$11:$AS$11,"Discount",$N$10:$AS$10,$B$204),"-") -> -
C25: 11.2 | D25: 1 | E25: Drive-up | F25: No | G25: =IFERROR((H25/$C25),"-") -> - | H25: =IFERROR(AVERAGEIFS(N25:AS25,$N$11:$AS$11,"Asking Rate",$N$10:$AS$10,$B$204),"-") -> - | I25: =IFERROR((J25/$C25),"-") -> - | J25: =IFERROR(AVERAGEIF($N$9:$AS$9,"<="&$B$3,N25:AS25),"-") -> - | K25: =IFERROR((L25/$C25),"-") -> - | L25: =IFERROR(AVERAGEIFS(N25:AS25,$N$11:$AS$11,"Discount",$N$10:$AS$10,$B$204),"-") -> -
B26: 3x3.80 | C26: 11.4 | D26: 1 | E26: Drive-up | F26: No | G26: =IFERROR((H26/$C26),"-") -> - | H26: =IFERROR(AVERAGEIFS(N26:AS26,$N$11:$AS$11,"Asking Rate",$N$10:$AS$10,$B$204),"-") -> - | I26: =IFERROR((J26/$C26),"-") -> - | J26: =IFERROR(AVERAGEIF($N$9:$AS$9,"<="&$B$3,N26:AS26),"-") -> - | K26: =IFERROR((L26/$C26),"-") -> - | L26: =IFERROR(AVERAGEIFS(N26:AS26,$N$11:$AS$11,"Discount",$N$10:$AS$10,$B$204),"-") -> -
B27: 3x4 | C27: 12 | D27: 1 | E27: Drive-up | F27: No | G27: =IFERROR((H27/$C27),"-") -> - | H27: =IFERROR(AVERAGEIFS(N27:AS27,$N$11:$AS$11,"Asking Rate",$N$10:$AS$10,$B$204),"-") -> - | I27: =IFERROR((J27/$C27),"-") -> - | J27: =IFERROR(AVERAGEIF($N$9:$AS$9,"<="&$B$3,N27:AS27),"-") -> - | K27: =IFERROR((L27/$C27),"-") -> - | L27: =IFERROR(AVERAGEIFS(N27:AS27,$N$11:$AS$11,"Discount",$N$10:$AS$10,$B$204),"-") -> -
B28: 3.5x4 | C28: 12.25 | D28: 1 | E28: Drive-up | F28: No | G28: =IFERROR((H28/$C28),"-") -> - | H28: =IFERROR(AVERAGEIFS(N28:AS28,$N$11:$AS$11,"Asking Rate",$N$10:$AS$10,$B$204),"-") -> - | I28: =IFERROR((J28/$C28),"-") -> - | J28: =IFERROR(AVERAGEIF($N$9:$AS$9,"<="&$B$3,N28:AS28),"-") -> - | K28: =IFERROR((L28/$C28),"-") -> - | L28: =IFERROR(AVERAGEIFS(N28:AS28,$N$11:$AS$11,"Discount",$N$10:$AS$10,$B$204),"-") -> -
B29: 4.5x2.8 | C29: 12.6 | D29: 1 | E29: Drive-up | F29: No | G29: =IFERROR((H29/$C29),"-") -> - | H29: =IFERROR(AVERAGEIFS(N29:AS29,$N$11:$AS$11,"Asking Rate",$N$10:$AS$10,$B$204),"-") -> - | I29: =IFERROR((J29/$C29),"-") -> - | J29: =IFERROR(AVERAGEIF($N$9:$AS$9,"<="&$B$3,N29:AS29),"-") -> - | K29: =IFERROR((L29/$C29),"-") -> - | L29: =IFERROR(AVERAGEIFS(N29:AS29,$N$11:$AS$11,"Discount",$N$10:$AS$10,$B$204),"-") -> -
B30: 4.5x3 | C30: 13.5 | D30: 1 | E30: Drive-up | F30: No | G30: =IFERROR((H30/$C30),"-") -> - | H30: =IFERROR(AVERAGEIFS(N30:AS30,$N$11:$AS$11,"Asking Rate",$N$10:$AS$10,$B$204),"-") -> - | I30: =IFERROR((J30/$C30),"-") -> - | J30: =IFERROR(AVERAGEIF($N$9:$AS$9,"<="&$B$3,N30:AS30),"-") -> - | K30: =IFERROR((L30/$C30),"-") -> - | L30: =IFERROR(AVERAGEIFS(N30:AS30,$N$11:$AS$11,"Discount",$N$10:$AS$10,$B$204),"-") -> -
B31: 3x5 | C31: 15 | D31: 1 | E31: Drive-up | F31: No | G31: =IFERROR((H31/$C31),"-") -> - | H31: =IFERROR(AVERAGEIFS(N31:AS31,$N$11:$AS$11,"Asking Rate",$N$10:$AS$10,$B$204),"-") -> - | I31: =IFERROR((J31/$C31),"-") -> - | J31: =IFERROR(AVERAGEIF($N$9:$AS$9,"<="&$B$3,N31:AS31),"-") -> - | K31: =IFERROR((L31/$C31),"-") -> - | L31: =IFERROR(AVERAGEIFS(N31:AS31,$N$11:$AS$11,"Discount",$N$10:$AS$10,$B$204),"-") -> -
B32: 4x4 | C32: 16 | D32: 1 | E32: Drive-up | F32: No | G32: =IFERROR((H32/$C32),"-") -> - | H32: =IFERROR(AVERAGEIFS(N32:AS32,$N$11:$AS$11,"Asking Rate",$N$10:$AS$10,$B$204),"-") -> - | I32: =IFERROR((J32/$C32),"-") -> - | J32: =IFERROR(AVERAGEIF($N$9:$AS$9,"<="&$B$3,N32:AS32),"-") -> - | K32: =IFERROR((L32/$C32),"-") -> - | L32: =IFERROR(AVERAGEIFS(N32:AS32,$N$11:$AS$11,"Discount",$N$10:$AS$10,$B$204),"-") -> -
C33: 16.24 | D33: 1 | E33: Drive-up | F33: No | G33: =IFERROR((H33/$C33),"-") -> - | H33: =IFERROR(AVERAGEIFS(N33:AS33,$N$11:$AS$11,"Asking Rate",$N$10:$AS$10,$B$204),"-") -> - | I33: =IFERROR((J33/$C33),"-") -> - | J33: =IFERROR(AVERAGEIF($N$9:$AS$9,"<="&$B$3,N33:AS33),"-") -> - | K33: =IFERROR((L33/$C33),"-") -> - | L33: =IFERROR(AVERAGEIFS(N33:AS33,$N$11:$AS$11,"Discount",$N$10:$AS$10,$B$204),"-") -> -
B34: 3x5.5 | C34: 16.5 | D34: 1 | E34: Drive-up | F34: No | G34: =IFERROR((H34/$C34),"-") -> - | H34: =IFERROR(AVERAGEIFS(N34:AS34,$N$11:$AS$11,"Asking Rate",$N$10:$AS$10,$B$204),"-") -> - | I34: =IFERROR((J34/$C34),"-") -> - | J34: =IFERROR(AVERAGEIF($N$9:$AS$9,"<="&$B$3,N34:AS34),"-") -> - | K34: =IFERROR((L34/$C34),"-") -> - | L34: =IFERROR(AVERAGEIFS(N34:AS34,$N$11:$AS$11,"Discount",$N$10:$AS$10,$B$204),"-") -> -
B35: 6x2.8 | C35: 16.8 | D35: 1 | E35: Drive-up | F35: No | G35: =IFERROR((H35/$C35),"-") -> - | H35: =IFERROR(AVERAGEIFS(N35:AS35,$N$11:$AS$11,"Asking Rate",$N$10:$AS$10,$B$204),"-") -> - | I35: =IFERROR((J35/$C35),"-") -> - | J35: =IFERROR(AVERAGEIF($N$9:$AS$9,"<="&$B$3,N35:AS35),"-") -> - | K35: =IFERROR((L35/$C35),"-") -> - | L35: =IFERROR(AVERAGEIFS(N35:AS35,$N$11:$AS$11,"Discount",$N$10:$AS$10,$B$204),"-") -> -
B36: 2.5x7 | C36: 17.5 | D36: 1 | E36: Drive-up | F36: No | G36: =IFERROR((H36/$C36),"-") -> - | H36: =IFERROR(AVERAGEIFS(N36:AS36,$N$11:$AS$11,"Asking Rate",$N$10:$AS$10,$B$204),"-") -> - | I36: =IFERROR((J36/$C36),"-") -> - | J36: =IFERROR(AVERAGEIF($N$9:$AS$9,"<="&$B$3,N36:AS36),"-") -> - | K36: =IFERROR((L36/$C36),"-") -> - | L36: =IFERROR(AVERAGEIFS(N36:AS36,$N$11:$AS$11,"Discount",$N$10:$AS$10,$B$204),"-") -> -
B37: 6x3 | C37: 18 | D37: 1 | E37: Drive-up | F37: No | G37: =IFERROR((H37/$C37),"-") -> - | H37: =IFERROR(AVERAGEIFS(N37:AS37,$N$11:$AS$11,"Asking Rate",$N$10:$AS$10,$B$204),"-") -> - | I37: =IFERROR((J37/$C37),"-") -> - | J37: =IFERROR(AVERAGEIF($N$9:$AS$9,"<="&$B$3,N37:AS37),"-") -> - | K37: =IFERROR((L37/$C37),"-") -> - | L37: =IFERROR(AVERAGEIFS(N37:AS37,$N$11:$AS$11,"Discount",$N$10:$AS$10,$B$204),"-") -> -
C38: 19.5 | D38: 1 | E38: Drive-up | F38: No | G38: =IFERROR((H38/$C38),"-") -> - | H38: =IFERROR(AVERAGEIFS(N38:AS38,$N$11:$AS$11,"Asking Rate",$N$10:$AS$10,$B$204),"-") -> - | I38: =IFERROR((J38/$C38),"-") -> - | J38: =IFERROR(AVERAGEIF($N$9:$AS$9,"<="&$B$3,N38:AS38),"-") -> - | K38: =IFERROR((L38/$C38),"-") -> - | L38: =IFERROR(AVERAGEIFS(N38:AS38,$N$11:$AS$11,"Discount",$N$10:$AS$10,$B$204),"-") -> -
B39: 3x7 | C39: 21 | D39: 1 | E39: Drive-up | F39: No | G39: =IFERROR((H39/$C39),"-") -> - | H39: =IFERROR(AVERAGEIFS(N39:AS39,$N$11:$AS$11,"Asking Rate",$N$10:$AS$10,$B$204),"-") -> - | I39: =IFERROR((J39/$C39),"-") -> - | J39: =IFERROR(AVERAGEIF($N$9:$AS$9,"<="&$B$3,N39:AS39),"-") -> - | K39: =IFERROR((L39/$C39),"-") -> - | L39: =IFERROR(AVERAGEIFS(N39:AS39,$N$11:$AS$11,"Discount",$N$10:$AS$10,$B$204),"-") -> -
B40: 3x7.5 | C40: 22.5 | D40: 1 | E40: Drive-up | F40: No | G40: =IFERROR((H40/$C40),"-") -> - | H40: =IFERROR(AVERAGEIFS(N40:AS40,$N$11:$AS$11,"Asking Rate",$N$10:$AS$10,$B$204),"-") -> - | I40: =IFERROR((J40/$C40),"-") -> - | J40: =IFERROR(AVERAGEIF($N$9:$AS$9,"<="&$B$3,N40:AS40),"-") -> - | K40: =IFERROR((L40/$C40),"-") -> - | L40: =IFERROR(AVERAGEIFS(N40:AS40,$N$11:$AS$11,"Discount",$N$10:$AS$10,$B$204),"-") -> -
B41: 8x3 | C41: 24 | D41: 1 | E41: Drive-up | F41: No | G41: =IFERROR((H41/$C41),"-") -> - | H41: =IFERROR(AVERAGEIFS(N41:AS41,$N$11:$AS$11,"Asking Rate",$N$10:$AS$10,$B$204),"-") -> - | I41: =IFERROR((J41/$C41),"-") -> - | J41: =IFERROR(AVERAGEIF($N$9:$AS$9,"<="&$B$3,N41:AS41),"-") -> - | K41: =IFERROR((L41/$C41),"-") -> - | L41: =IFERROR(AVERAGEIFS(N41:AS41,$N$11:$AS$11,"Discount",$N$10:$AS$10,$B$204),"-") -> -
...

Sheet Workstore Sales
B2: Number of units | C2: =$B$33 -> 15
B3: Rate/m2 | C3: 5300
B4: Commission | C4: 0.03
B5: Average Unit Size | C5: =AVERAGE(C11:C32) -> 0
B6: Floor Area | C6: =$E$33 -> 0
B8: Workstores Unit Mix | G8: Workstore Sales
M9: Notes
B10: Unit No. | C10: Ground Floor (m2) | D10: Mezzanine (m2) | E10: Total (m2) | G10: Unit No. | H10: Sale Month | I10: Sale Price (GF) | J10: Commission | K10: Total
B11: 1 | C11: 0 | E11: =C11+D11 -> 0 | G11: =B11 -> 1 | H11: 15 | I11: =E11*$C$3 -> 0 | J11: =I11*$C$4 -> 0 | K11: =I11-J11 -> 0
B12: 2 | C12: 0 | E12: =C12+D12 -> 0 | G12: =B12 -> 2 | H12: 15 | I12: =E12*$C$3 -> 0 | J12: =I12*$C$4 -> 0 | K12: =I12-J12 -> 0
B13: 3 | C13: 0 | E13: =C13+D13 -> 0 | G13: =B13 -> 3 | H13: 15 | I13: =E13*$C$3 -> 0 | J13: =I13*$C$4 -> 0 | K13: =I13-J13 -> 0
B14: 4 | C14: 0 | E14: =C14+D14 -> 0 | G14: =B14 -> 4 | H14: 15 | I14: =E14*$C$3 -> 0 | J14: =I14*$C$4 -> 0 | K14: =I14-J14 -> 0
B15: 5 | C15: 0 | E15: =C15+D15 -> 0 | G15: =B15 -> 5 | H15: 15 | I15: =E15*$C$3 -> 0 | J15: =I15*$C$4 -> 0 | K15: =I15-J15 -> 0
B16: 6 | C16: 0 | E16: =C16+D16 -> 0 | G16: =B16 -> 6 | H16: 15 | I16: =E16*$C$3 -> 0 | J16: =I16*$C$4 -> 0 | K16: =I16-J16 -> 0
B17: 7 | C17: 0 | E17: =C17+D17 -> 0 | G17: =B17 -> 7 | H17: 15 | I17: =E17*$C$3 -> 0 | J17: =I17*$C$4 -> 0 | K17: =I17-J17 -> 0
B18: 8 | C18: 0 | E18: =C18+D18 -> 0 | G18: =B18 -> 8 | H18: 16 | I18: =E18*$C$3 -> 0 | J18: =I18*$C$4 -> 0 | K18: =I18-J18 -> 0
B19: 9 | C19: 0 | E19: =C19+D19 -> 0 | G19: =B19 -> 9 | H19: 16 | I19: =E19*$C$3 -> 0 | J19: =I19*$C$4 -> 0 | K19: =I19-J19 -> 0
B20: 10 | C20: 0 | E20: =C20+D20 -> 0 | G20: =B20 -> 10 | H20: 17 | I20: =E20*$C$3 -> 0 | J20: =I20*$C$4 -> 0 | K20: =I20-J20 -> 0
B21: 11 | C21: 0 | E21: =C21+D21 -> 0 | G21: =B21 -> 11 | H21: 17 | I21: =E21*$C$3 -> 0 | J21: =I21*$C$4 -> 0 | K21: =I21-J21 -> 0
B22: 12 | C22: 0 | E22: =C22+D22 -> 0 | G22: =B22 -> 12 | H22: 18 | I22: =E22*$C$3 -> 0 | J22: =I22*$C$4 -> 0 | K22: =I22-J22 -> 0
... B25: 15 | C25: 0 | E25: =C25+D25 -> 0 | G25: =B25 -> 15 | H25: 19 | I25: =E25*$C$3 -> 0 | J25: =I25*$C$4 -> 0 | K25: =I25-J25 -> 0
E26: =C26+D26 -> 0 | G26: =B26 -> 0 | H26: 20 | I26: =E26*$C$3 -> 0 | J26: =I26*$C$4 -> 0 | K26: =I26-J26 -> 0
E27: =C27+D27 -> 0 | G27: =B27 -> 0 | H27: 20 | I27: =E27*$C$3 -> 0 | J27: =I27*$C$4 -> 0 | K27: =I27-J27 -> 0
E28: =C28+D28 -> 0 | G28: =B28 -> 0 | H28: 21 | I28: =E28*$C$3 -> 0 | J28: =I28*$C$4 -> 0 | K28: =I28-J28 -> 0
E29: =C29+D29 -> 0 | G29: =B29 -> 0 | I29: =E29*$C$3 -> 0 | J29: =I29*$C$4 -> 0 | K29: =I29-J29 -> 0
E30: =C30+D30 -> 0 | G30: =B30 -> 0 | I30: =E30*$C$3 -> 0 | J30: =I30*$C$4 -> 0 | K30: =I30-J30 -> 0
E31: =C31+D31 -> 0 | G31: =B31 -> 0 | I31: =E31*$C$3 -> 0 | J31: =I31*$C$4 -> 0 | K31: =I31-J31 -> 0
E32: =C32+D32 -> 0 | G32: =B32 -> 0 | I32: =E32*$C$3 -> 0 | J32: =I32*$C$4 -> 0 | K32: =I32-J32 -> 0
